<?xml version="1.0" encoding="utf-8"?>
<!-- This URDF was automatically created by SolidWorks to URDF Exporter! Originally created by Stephen Brawner (brawner@gmail.com) 
     Commit Version: 1.6.0-4-g7f85cfe  Build Version: 1.6.7995.38578
     For more information, please see http://wiki.ros.org/sw_urdf_exporter -->
<robot
  name="ia_robot">
  <link
    name="base_link">
    <inertial>
      <origin
        xyz="0.037909 0.00021539 0.8026"
        rpy="0 0 0" />
      <mass
        value="42.189" />
      <inertia
        ixx="0.60924"
        ixy="-1.347E-07"
        ixz="0.0040799"
        iyy="0.39675"
        iyz="-6.3541E-06"
        izz="0.41271" />
    </inertial>
    <visual>
      <origin
        xyz="0 0 0"
        rpy="0 0 0" />
      <geometry>
        <mesh
          filename="package://ia_robot/meshes/base_link.stl" />
      </geometry>
      <material
        name="">
        <color
          rgba="0.75294 0.75294 0.75294 1" />
      </material>
    </visual>
    <collision>
      <origin
        xyz="0 0 0"
        rpy="0 0 0" />
      <geometry>
        <mesh
          filename="package://ia_robot/meshes/base_link.stl" />
      </geometry>
    </collision>
  </link>
  <joint
    name="leftbackwheel01"
    type="continuous">
    <origin
      xyz="-2.8509E-05 -0.0019998 -0.11"
      rpy="1.5708 0 3.1416" />
    <parent
      link="leftbackorient" />
    <child
      link="leftbackwheel" />
    <axis
      xyz="0 0 -1" />
    <limit
      effort="50"
      velocity="0" />
  </joint>
  <link
    name="leftbackorient">
    <inertial>
      <origin
        xyz="-0.00048945 -0.034334 -0.028302"
        rpy="0 0 0" />
      <mass
        value="0.21206" />
      <inertia
        ixx="0.00050188"
        ixy="-7.6737E-07"
        ixz="-1.9027E-06"
        iyy="0.00044807"
        iyz="-0.00013346"
        izz="0.00041211" />
    </inertial>
    <visual>
      <origin
        xyz="0 0 0"
        rpy="0 0 0" />
      <geometry>
        <mesh
          filename="package://ia_robot/meshes/leftbackorient.stl" />
      </geometry>
      <material
        name="">
        <color
          rgba="0.89804 0.91765 0.92941 1" />
      </material>
    </visual>
    <collision>
      <origin
        xyz="0 0 0"
        rpy="0 0 0" />
      <geometry>
        <mesh
          filename="package://ia_robot/meshes/leftbackorient.stl" />
      </geometry>
    </collision>
  </link>
  <joint
    name="leftbackorient01"
    type="continuous">
    <origin
      xyz="0.5 -0.2635 0.18937"
      rpy="0 0 0" />
    <parent
      link="base_link" />
    <child
      link="leftbackorient" />
    <axis
      xyz="0 0 -1" />
    <limit
      effort="13.5"
      velocity="0" />
  </joint>
  <link
    name="leftbackwheel">
    <inertial>
      <origin
        xyz="0 0 -0.00020767"
        rpy="0 0 0" />
      <mass
        value="3.6182" />
      <inertia
        ixx="0.0065597"
        ixy="7.8927E-20"
        ixz="3.0493E-19"
        iyy="0.0065597"
        iyz="-3.7641E-19"
        izz="0.0096608" />
    </inertial>
    <visual>
      <origin
        xyz="0 0 0"
        rpy="0 0 0" />
      <geometry>
        <mesh
          filename="package://ia_robot/meshes/leftbackwheel.stl" />
      </geometry>
      <material
        name="">
        <color
          rgba="0.89804 0.91765 0.92941 1" />
      </material>
    </visual>
    <collision>
      <origin
        xyz="0 0 0"
        rpy="0 0 0" />
      <geometry>
        <mesh
          filename="package://ia_robot/meshes/leftbackwheel.stl" />
      </geometry>
    </collision>
  </link>
  <link
    name="Rightbackorient">
    <inertial>
      <origin
        xyz="-0.0027669 0.034225 -0.028302"
        rpy="0 0 0" />
      <mass
        value="0.21206" />
      <inertia
        ixx="0.00050155"
        ixy="4.3244E-06"
        ixz="-1.0756E-05"
        iyy="0.0004484"
        iyz="0.00013304"
        izz="0.00041211" />
    </inertial>
    <visual>
      <origin
        xyz="0 0 0"
        rpy="0 0 0" />
      <geometry>
        <mesh
          filename="package://ia_robot/meshes/Rightbackorient.stl" />
      </geometry>
      <material
        name="">
        <color
          rgba="0.89804 0.91765 0.92941 1" />
      </material>
    </visual>
    <collision>
      <origin
        xyz="0 0 0"
        rpy="0 0 0" />
      <geometry>
        <mesh
          filename="package://ia_robot/meshes/Rightbackorient.stl" />
      </geometry>
    </collision>
  </link>
  <joint
    name="Rightbackorient-1"
    type="continuous">
    <origin
      xyz="0.5 0.2635 0.18937"
      rpy="0 0 0" />
    <parent
      link="base_link" />
    <child
      link="Rightbackorient" />
    <axis
      xyz="0 0 -1" />
    <limit
      effort="13.5"
      velocity="0" />
  </joint>
  <link
    name="Rightbackwheel">
    <inertial>
      <origin
        xyz="-1.67345419225806E-05 1.11022302462516E-16 -0.000206996303198315"
        rpy="0 0 0" />
      <mass
        value="3.61818023273865" />
      <inertia
        ixx="0.00657987024245532"
        ixy="7.49384900018109E-20"
        ixz="0.000249074423068998"
        iyy="0.00655966618652465"
        iyz="-3.63354164127521E-19"
        izz="0.0096406359768352" />
    </inertial>
    <visual>
      <origin
        xyz="0 0 0"
        rpy="0 0 0" />
      <geometry>
        <mesh
          filename="package://ia_robot/meshes/Rightbackwheel.stl" />
      </geometry>
      <material
        name="">
        <color
          rgba="0.898039215686275 0.917647058823529 0.929411764705882 1" />
      </material>
    </visual>
    <collision>
      <origin
        xyz="0 0 0"
        rpy="0 0 0" />
      <geometry>
        <mesh
          filename="package://ia_robot/meshes/Rightbackwheel.stl" />
      </geometry>
    </collision>
  </link>
  <joint
    name="Rightbackwheel-1"
    type="continuous">
    <origin
      xyz="-0.000161163470126346 0.00199349600849796 -0.11"
      rpy="1.5708 0 0" />
    <parent
      link="Rightbackorient" />
    <child
      link="Rightbackwheel" />
    <axis
      xyz="-0.08058173506303 0 -0.996748004248933" />
    <limit
      effort="50"
      velocity="0" />
  </joint>
  <link
    name="LeftFrontWheelOrient2">
    <inertial>
      <origin
        xyz="-0.11285418489353 0.00356568192950379 0.0139762389318379"
        rpy="0 0 0" />
      <mass
        value="0.427167332080997" />
      <inertia
        ixx="0.000418522032180055"
        ixy="4.89846927753665E-05"
        ixz="4.27468579690659E-05"
        iyy="0.00190242881630566"
        iyz="-2.39309753871588E-07"
        izz="0.00211243261005077" />
    </inertial>
    <visual>
      <origin
        xyz="0 0 0"
        rpy="0 0 0" />
      <geometry>
        <mesh
          filename="package://ia_robot/meshes/LeftFrontWheelOrient2.stl" />
      </geometry>
      <material
        name="">
        <color
          rgba="0.752941176470588 0.752941176470588 0.752941176470588 1" />
      </material>
    </visual>
    <collision>
      <origin
        xyz="0 0 0"
        rpy="0 0 0" />
      <geometry>
        <mesh
          filename="package://ia_robot/meshes/LeftFrontWheelOrient2.stl" />
      </geometry>
    </collision>
  </link>
  <joint
    name="LeftFrontWheelOrient2-1"
    type="continuous">
    <origin
      xyz="-0.32 -0.2635 0.20475"
      rpy="0 0 0" />
    <parent
      link="base_link" />
    <child
      link="LeftFrontWheelOrient2" />
    <axis
      xyz="0 0 -1" />
    <limit
      effort="49"
      velocity="0" />
  </joint>
  <link
    name="LeftFrontWheelOrient1">
    <inertial>
      <origin
        xyz="-0.000948507831906586 0.0343239444320287 -0.0283016270647419"
        rpy="0 0 0" />
      <mass
        value="0.212057188740176" />
      <inertia
        ixx="0.000501854273498574"
        ixy="1.48669107184792E-06"
        ixz="-3.687019665672E-06"
        iyy="0.000448096442339725"
        iyz="0.000133424417808254"
        izz="0.000412109578902224" />
    </inertial>
    <visual>
      <origin
        xyz="0 0 0"
        rpy="0 0 0" />
      <geometry>
        <mesh
          filename="package://ia_robot/meshes/LeftFrontWheelOrient1.stl" />
      </geometry>
      <material
        name="">
        <color
          rgba="0.898039215686275 0.917647058823529 0.929411764705882 1" />
      </material>
    </visual>
    <collision>
      <origin
        xyz="0 0 0"
        rpy="0 0 0" />
      <geometry>
        <mesh
          filename="package://ia_robot/meshes/LeftFrontWheelOrient1.stl" />
      </geometry>
    </collision>
  </link>
  <joint
    name="LeftFrontWheelOrient1-1"
    type="continuous">
    <origin
      xyz="-0.179905283136192 0.00583858713100255 -0.0146000000000007"
      rpy="0 0 3.1416" />
    <parent
      link="LeftFrontWheelOrient2" />
    <child
      link="LeftFrontWheelOrient1" />
    <axis
      xyz="0 0 -1" />
    <limit
      effort="13.5"
      velocity="0" />
  </joint>
  <link
    name="LeftFrontwheel">
    <inertial>
      <origin
        xyz="1.11022302462516E-16 1.11022302462516E-16 -0.000207671650523461"
        rpy="0 0 0" />
      <mass
        value="3.61818023273865" />
      <inertia
        ixx="0.00655973110012054"
        ixy="-1.3505572451808E-08"
        ixz="8.40256683676266E-19"
        iyy="0.00655966899642117"
        iyz="-8.51314352824881E-19"
        izz="0.00966077230927346" />
    </inertial>
    <visual>
      <origin
        xyz="0 0 0"
        rpy="0 0 0" />
      <geometry>
        <mesh
          filename="package://ia_robot/meshes/LeftFrontwheel.stl" />
      </geometry>
      <material
        name="">
        <color
          rgba="0.898039215686275 0.917647058823529 0.929411764705882 1" />
      </material>
    </visual>
    <collision>
      <origin
        xyz="0 0 0"
        rpy="0 0 0" />
      <geometry>
        <mesh
          filename="package://ia_robot/meshes/LeftFrontwheel.stl" />
      </geometry>
    </collision>
  </link>
  <joint
    name="LeftFrontwheel-1"
    type="continuous">
    <origin
      xyz="-5.52466221374059E-05 0.00199923680706893 -0.11"
      rpy="1.5708 0 0" />
    <parent
      link="LeftFrontWheelOrient1" />
    <child
      link="LeftFrontwheel" />
    <axis
      xyz="0 0 -1" />
    <limit
      effort="50"
      velocity="0" />
  </joint>
  <link
    name="RightFrontWheelOrient2">
    <inertial>
      <origin
        xyz="-0.112910374002102 0.00016905120845867 0.0139762389318376"
        rpy="0 0 0" />
      <mass
        value="0.427167332080998" />
      <inertia
        ixx="0.000416919067382263"
        ixy="4.27554581620662E-06"
        ixz="4.27347098463978E-05"
        iyy="0.00190403178110341"
        iyz="1.04676154423375E-06"
        izz="0.00211243261005077" />
    </inertial>
    <visual>
      <origin
        xyz="0 0 0"
        rpy="0 0 0" />
      <geometry>
        <mesh
          filename="package://ia_robot/meshes/RightFrontWheelOrient2.stl" />
      </geometry>
      <material
        name="">
        <color
          rgba="0.752941176470588 0.752941176470588 0.752941176470588 1" />
      </material>
    </visual>
    <collision>
      <origin
        xyz="0 0 0"
        rpy="0 0 0" />
      <geometry>
        <mesh
          filename="package://ia_robot/meshes/RightFrontWheelOrient2.stl" />
      </geometry>
    </collision>
  </link>
  <joint
    name="RightFrontWheelOrient2-1"
    type="continuous">
    <origin
      xyz="-0.32 0.2635 0.20412"
      rpy="0 0 0" />
    <parent
      link="base_link" />
    <child
      link="RightFrontWheelOrient2" />
    <axis
      xyz="0 0 -1" />
    <limit
      effort="49"
      velocity="0" />
  </joint>
  <link
    name="RightFrontWheelOrient01">
    <inertial>
      <origin
        xyz="-0.00182113120158134 0.0342887189825656 -0.0283016221542728"
        rpy="0 0 0" />
      <mass
        value="0.212057174883898" />
      <inertia
        ixx="0.000501743833498989"
        ixy="2.8515022611008E-06"
        ixz="-7.07907323328318E-06"
        iyy="0.000448206722575077"
        iyz="0.000133287481761764"
        izz="0.000412109562839574" />
    </inertial>
    <visual>
      <origin
        xyz="0 0 0"
        rpy="0 0 0" />
      <geometry>
        <mesh
          filename="package://ia_robot/meshes/RightFrontWheelOrient01.stl" />
      </geometry>
      <material
        name="">
        <color
          rgba="0.898039215686275 0.917647058823529 0.929411764705882 1" />
      </material>
    </visual>
    <collision>
      <origin
        xyz="0 0 0"
        rpy="0 0 0" />
      <geometry>
        <mesh
          filename="package://ia_robot/meshes/RightFrontWheelOrient01.stl" />
      </geometry>
    </collision>
  </link>
  <joint
    name="RightFrontWheelOrient01-1"
    type="continuous">
    <origin
      xyz="-0.18 0.00042381 -0.0146"
      rpy="0 0 0" />
    <parent
      link="RightFrontWheelOrient2" />
    <child
      link="RightFrontWheelOrient01" />
    <axis
      xyz="0 0 -1" />
    <limit
      effort="13.5"
      velocity="0" />
  </joint>
  <link
    name="RightFrontWheelOrient1">
    <inertial>
      <origin
        xyz="0 0 -0.000207671650523433"
        rpy="0 0 0" />
      <mass
        value="3.61818023273865" />
      <inertia
        ixx="0.00655973110012055"
        ixy="-1.35055724514069E-08"
        ixz="-7.58941520739853E-19"
        iyy="0.00655966899642118"
        iyz="-1.72204598307509E-20"
        izz="0.00966077230927346" />
    </inertial>
    <visual>
      <origin
        xyz="0 0 0"
        rpy="0 0 0" />
      <geometry>
        <mesh
          filename="package://ia_robot/meshes/RightFrontWheelOrient1.stl" />
      </geometry>
      <material
        name="">
        <color
          rgba="0.898039215686275 0.917647058823529 0.929411764705882 1" />
      </material>
    </visual>
    <collision>
      <origin
        xyz="0 0 0"
        rpy="0 0 0" />
      <geometry>
        <mesh
          filename="package://ia_robot/meshes/RightFrontWheelOrient1.stl" />
      </geometry>
    </collision>
  </link>
  <joint
    name="RightFrontWheel"
    type="continuous">
    <origin
      xyz="-0.00010607 0.0019972 -0.11"
      rpy="1.5708 0 0" />
    <parent
      link="RightFrontWheelOrient01" />
    <child
      link="RightFrontWheelOrient1" />
    <axis
      xyz="0 0 -1" />
    <limit
      effort="50"
      velocity="0" />
  </joint>
  <link
    name="LeftARM1">
    <inertial>
      <origin
        xyz="0.0857028873433471 -7.9505648153122E-05 0.0224604601278706"
        rpy="0 0 0" />
      <mass
        value="1.82195171111395" />
      <inertia
        ixx="0.00497485901808976"
        ixy="5.45710505076505E-06"
        ixz="-0.00199391908800169"
        iyy="0.010857324827174"
        iyz="1.84973732356237E-06"
        izz="0.0115954323258876" />
    </inertial>
    <visual>
      <origin
        xyz="0 0 0"
        rpy="0 0 0" />
      <geometry>
        <mesh
          filename="package://ia_robot/meshes/LeftARM1.stl" />
      </geometry>
      <material
        name="">
        <color
          rgba="0.752941176470588 0.752941176470588 0.752941176470588 1" />
      </material>
    </visual>
    <collision>
      <origin
        xyz="0 0 0"
        rpy="0 0 0" />
      <geometry>
        <mesh
          filename="package://ia_robot/meshes/LeftARM1.stl" />
      </geometry>
    </collision>
  </link>
  <joint
    name="LeftARMJoint1"
    type="continuous">
    <origin
      xyz="0 -0.195 1"
      rpy="1.5708 0 0" />
    <parent
      link="base_link" />
    <child
      link="LeftARM1" />
    <axis
      xyz="0 0 1" />
    <limit
      effort="267"
      velocity="0" />
  </joint>
  <link
    name="LeftARM02">
    <inertial>
      <origin
        xyz="0.0071369 -0.00047892 0.13771"
        rpy="0 0 0" />
      <mass
        value="0.27589" />
      <inertia
        ixx="0.00035994"
        ixy="-1.0176E-07"
        ixz="-2.8551E-05"
        iyy="0.00035843"
        iyz="1.916E-06"
        izz="0.00019777" />
    </inertial>
    <visual>
      <origin
        xyz="0 0 0"
        rpy="0 0 0" />
      <geometry>
        <mesh
          filename="package://ia_robot/meshes/LeftARM02.stl" />
      </geometry>
      <material
        name="">
        <color
          rgba="0.75294 0.75294 0.75294 1" />
      </material>
    </visual>
    <collision>
      <origin
        xyz="0 0 0"
        rpy="0 0 0" />
      <geometry>
        <mesh
          filename="package://ia_robot/meshes/LeftARM02.stl" />
      </geometry>
    </collision>
  </link>
  <joint
    name="LeftARMJoint02"
    type="continuous">
    <origin
      xyz="0.12634 -0.0001172 0.073"
      rpy="3.1416 -1.5708 3.1416" />
    <parent
      link="LeftARM1" />
    <child
      link="LeftARM02" />
    <axis
      xyz="0 0 -1" />
    <limit
      effort="49"
      velocity="0" />
  </joint>
  <link
    name="LeftARM03">
    <inertial>
      <origin
        xyz="-0.33877 0.022556 -0.037558"
        rpy="0 0 0" />
      <mass
        value="0.47985" />
      <inertia
        ixx="0.00039931"
        ixy="0.00017623"
        ixz="-4.1078E-05"
        iyy="0.0031806"
        iyz="2.679E-06"
        izz="0.0031962" />
    </inertial>
    <visual>
      <origin
        xyz="0 0 0"
        rpy="0 0 0" />
      <geometry>
        <mesh
          filename="package://ia_robot/meshes/LeftARM03.stl" />
      </geometry>
      <material
        name="">
        <color
          rgba="0.75294 0.75294 0.75294 1" />
      </material>
    </visual>
    <collision>
      <origin
        xyz="0 0 0"
        rpy="0 0 0" />
      <geometry>
        <mesh
          filename="package://ia_robot/meshes/LeftARM03.stl" />
      </geometry>
    </collision>
  </link>
  <joint
    name="LeftARMJoint03"
    type="continuous">
    <origin
      xyz="0.059067 -0.003961 0.28311"
      rpy="1.5708 1.5708 1.5708" />
    <parent
      link="LeftARM02" />
    <child
      link="LeftARM03" />
    <axis
      xyz="0 0 1" />
    <limit
      lower="0"
      upper="0"
      effort="133"
      velocity="0" />
  </joint>
  <link
    name="LeftEnd">
    <inertial>
      <origin
        xyz="-0.11892 0.0078495 -0.029023"
        rpy="0 0 0" />
      <mass
        value="0.5725" />
      <inertia
        ixx="0.00048907"
        ixy="0.00010933"
        ixz="-0.00011104"
        iyy="0.0021383"
        iyz="7.3296E-06"
        izz="0.0021312" />
    </inertial>
    <visual>
      <origin
        xyz="0 0 0"
        rpy="0 0 0" />
      <geometry>
        <mesh
          filename="package://ia_robot/meshes/LeftEnd.stl" />
      </geometry>
      <material
        name="">
        <color
          rgba="0.75294 0.75294 0.75294 1" />
      </material>
    </visual>
    <collision>
      <origin
        xyz="0 0 0"
        rpy="0 0 0" />
      <geometry>
        <mesh
          filename="package://ia_robot/meshes/LeftEnd.stl" />
      </geometry>
    </collision>
  </link>
  <joint
    name="LeftEndJoint"
    type="continuous">
    <origin
      xyz="-0.66222 0.086205 -0.049114"
      rpy="-1.5708 0 0" />
    <parent
      link="LeftARM03" />
    <child
      link="LeftEnd" />
    <axis
      xyz="0 0 1" />
    <limit
      lower="0"
      upper="0"
      effort="61"
      velocity="0" />
  </joint>
  <link
    name="RightARM1">
    <inertial>
      <origin
        xyz="0.085703 7.9506E-05 0.02246"
        rpy="0 0 0" />
      <mass
        value="1.822" />
      <inertia
        ixx="0.0049749"
        ixy="-5.4571E-06"
        ixz="-0.0019939"
        iyy="0.010857"
        iyz="-1.8497E-06"
        izz="0.011595" />
    </inertial>
    <visual>
      <origin
        xyz="0 0 0"
        rpy="0 0 0" />
      <geometry>
        <mesh
          filename="package://ia_robot/meshes/RightARM1.stl" />
      </geometry>
      <material
        name="">
        <color
          rgba="0.75294 0.75294 0.75294 1" />
      </material>
    </visual>
    <collision>
      <origin
        xyz="0 0 0"
        rpy="0 0 0" />
      <geometry>
        <mesh
          filename="package://ia_robot/meshes/RightARM1.stl" />
      </geometry>
    </collision>
  </link>
  <joint
    name="RightARMJoint1"
    type="continuous">
    <origin
      xyz="0 0.195 1"
      rpy="-1.5708 0 0" />
    <parent
      link="base_link" />
    <child
      link="RightARM1" />
    <axis
      xyz="0 0 1" />
    <limit
      effort="267"
      velocity="0" />
  </joint>
  <link
    name="RihgtARM2">
    <inertial>
      <origin
        xyz="0.0070917 -0.00093374 0.13771"
        rpy="0 0 0" />
      <mass
        value="0.27589" />
      <inertia
        ixx="0.00035992"
        ixy="-1.9718E-07"
        ixz="-2.8371E-05"
        iyy="0.00035845"
        iyz="3.7355E-06"
        izz="0.00019777" />
    </inertial>
    <visual>
      <origin
        xyz="0 0 0"
        rpy="0 0 0" />
      <geometry>
        <mesh
          filename="package://ia_robot/meshes/RihgtARM2.stl" />
      </geometry>
      <material
        name="">
        <color
          rgba="0.75294 0.75294 0.75294 1" />
      </material>
    </visual>
    <collision>
      <origin
        xyz="0 0 0"
        rpy="0 0 0" />
      <geometry>
        <mesh
          filename="package://ia_robot/meshes/RihgtARM2.stl" />
      </geometry>
    </collision>
  </link>
  <joint
    name="RihgtARMJoint2"
    type="continuous">
    <origin
      xyz="0.126339132538937 0.000117203456298176 0.0729999999999077"
      rpy="1.5708 -1.5708 -1.5708" />
    <parent
      link="RightARM1" />
    <child
      link="RihgtARM2" />
    <axis
      xyz="0 0 -1" />
    <limit
      effort="49"
      velocity="0" />
  </joint>
  <link
    name="RightARM3">
    <inertial>
      <origin
        xyz="-0.33947 -0.006255 0.037558"
        rpy="0 0 0" />
      <mass
        value="0.47985" />
      <inertia
        ixx="0.00038882"
        ixy="-4.1952E-05"
        ixz="4.116E-05"
        iyy="0.0031911"
        iyz="7.025E-07"
        izz="0.0031962" />
    </inertial>
    <visual>
      <origin
        xyz="0 0 0"
        rpy="0 0 0" />
      <geometry>
        <mesh
          filename="package://ia_robot/meshes/RightARM3.stl" />
      </geometry>
      <material
        name="">
        <color
          rgba="0.75294 0.75294 0.75294 1" />
      </material>
    </visual>
    <collision>
      <origin
        xyz="0 0 0"
        rpy="0 0 0" />
      <geometry>
        <mesh
          filename="package://ia_robot/meshes/RightARM3.stl" />
      </geometry>
    </collision>
  </link>
  <joint
    name="RightARMJoint3"
    type="continuous">
    <origin
      xyz="0.058694 -0.0077252 0.28311"
      rpy="-1.5708 1.5708 1.5708" />
    <parent
      link="RihgtARM2" />
    <child
      link="RightARM3" />
    <axis
      xyz="0 0 -1" />
    <limit
      lower="0"
      upper="0"
      effort="133"
      velocity="0" />
  </joint>
  <link
    name="RightEnd">
    <inertial>
      <origin
        xyz="0.0021964 -0.11916 -0.029023"
        rpy="0 0 0" />
      <mass
        value="0.5725" />
      <inertia
        ixx="0.0021449"
        ixy="3.0654E-05"
        ixz="2.0508E-06"
        iyy="0.00048242"
        iyz="-0.00011126"
        izz="0.0021312" />
    </inertial>
    <visual>
      <origin
        xyz="0 0 0"
        rpy="0 0 0" />
      <geometry>
        <mesh
          filename="package://ia_robot/meshes/RightEnd.stl" />
      </geometry>
      <material
        name="">
        <color
          rgba="0.75294 0.75294 0.75294 1" />
      </material>
    </visual>
    <collision>
      <origin
        xyz="0 0 0"
        rpy="0 0 0" />
      <geometry>
        <mesh
          filename="package://ia_robot/meshes/RightEnd.stl" />
      </geometry>
    </collision>
  </link>
  <joint
    name="RightEndJOINT"
    type="continuous">
    <origin
      xyz="-0.66559 -0.054292 0.049114"
      rpy="1.5708 1.5708 0" />
    <parent
      link="RightARM3" />
    <child
      link="RightEnd" />
    <axis
      xyz="0 0 1" />
    <limit
      lower="0"
      upper="0"
      effort="61"
      velocity="0" />
  </joint>
</robot>