<?xml version="1.0" encoding="utf-8"?>
<!-- This URDF was automatically created by SolidWorks to URDF Exporter! Originally created by Stephen Brawner (brawner@gmail.com) 
     Commit Version: 1.6.0-4-g7f85cfe  Build Version: 1.6.7995.38578
     For more information, please see http://wiki.ros.org/sw_urdf_exporter -->
<robot
  name="ia_robot">
  <link
    name="base_link">
    <inertial>
      <origin
        xyz="0.18038 -0.0015014 0.55466"
        rpy="0 0 0" />
      <mass
        value="40" />
      <inertia
        ixx="0.10843"
        ixy="-6.4739E-06"
        ixz="0.00065952"
        iyy="0.095409"
        iyz="-0.00012632"
        izz="0.0959" />
    </inertial>
    <visual>
      <origin
        xyz="0 0 0"
        rpy="0 0 0" />
      <geometry>
        <mesh
          filename="package://ia_robot/meshes/base_link_new.stl" />
      </geometry>
      <material
        name="">
        <color
          rgba="0.75294 0.75294 0.75294 1" />
      </material>
    </visual>
    <collision>
      <origin
        xyz="0 0 0"
        rpy="0 0 0" />
      <geometry>
        <mesh
          filename="package://ia_robot/meshes/base_link_new.stl" />
      </geometry>
    </collision>
  </link>
  <link
    name="right_back_turn">
    <inertial>
      <origin
        xyz="-0.023257 -0.02638 -0.019921"
        rpy="0 0 0" />
      <mass
        value="0.2" />
      <inertia
        ixx="0.00046931"
        ixy="-2.4683E-05"
        ixz="-8.6444E-05"
        iyy="0.00046307"
        iyz="-9.8051E-05"
        izz="0.00040411" />
    </inertial>
    <visual>
      <origin
        xyz="0 0 0"
        rpy="0 0 0" />
      <geometry>
        <mesh
          filename="package://ia_robot/meshes/right_back_turn.stl" />
      </geometry>
      <material
        name="">
        <color
          rgba="0.89804 0.91765 0.92941 1" />
      </material>
    </visual>
    <collision>
      <origin
        xyz="0 0 0"
        rpy="0 0 0" />
      <geometry>
        <mesh
          filename="package://ia_robot/meshes/right_back_turn.stl" />
      </geometry>
    </collision>
  </link>
  <joint
    name="right_back_turn"
    type="continuous">
    <origin
      xyz="0.5 0.2635 0.181"
      rpy="0 0 0" />
    <parent
      link="base_link" />
    <child
      link="right_back_turn" />
    <axis
      xyz="0 0 -1" />
  </joint>
  <link
    name="right_back_rotate">
    <inertial>
      <origin
        xyz="7.7687E-05 0.00017093 0.027435"
        rpy="0 0 0" />
      <mass
        value="5" />
      <inertia
        ixx="0.0024638"
        ixy="-7.1305E-06"
        ixz="-5.047E-06"
        iyy="0.0024513"
        iyz="-1.1105E-05"
        izz="0.0035968" />
    </inertial>
    <visual>
      <origin
        xyz="0 0 0"
        rpy="0 0 0" />
      <geometry>
        <mesh
          filename="package://ia_robot/meshes/right_back_rotate.stl" />
      </geometry>
      <material
        name="">
        <color
          rgba="1 1 1 1" />
      </material>
    </visual>
    <collision>
      <origin
        xyz="0 0 0"
        rpy="0 0 0" />
      <geometry>
        <mesh
          filename="package://ia_robot/meshes/right_back_rotate.stl" />
      </geometry>
    </collision>
  </link>
  <joint
    name="right_back_rotate"
    type="continuous">
    <origin
      xyz="0.014549 0.016502 -0.101"
      rpy="1.5708 0 -0.72257" />
    <parent
      link="right_back_turn" />
    <child
      link="right_back_rotate" />
    <axis
      xyz="0 0 -1" />
  </joint>
  <link
    name="left_back_turn">
    <inertial>
      <origin
        xyz="-0.022078 -0.027374 -0.019921"
        rpy="0 0 0" />
      <mass
        value="0.2" />
      <inertia
        ixx="0.00047146"
        ixy="-2.4315E-05"
        ixz="-8.2062E-05"
        iyy="0.00046092"
        iyz="-0.00010175"
        izz="0.00040411" />
    </inertial>
    <visual>
      <origin
        xyz="0 0 0"
        rpy="0 0 0" />
      <geometry>
        <mesh
          filename="package://ia_robot/meshes/left_back_turn.stl" />
      </geometry>
      <material
        name="">
        <color
          rgba="0.89804 0.91765 0.92941 1" />
      </material>
    </visual>
    <collision>
      <origin
        xyz="0 0 0"
        rpy="0 0 0" />
      <geometry>
        <mesh
          filename="package://ia_robot/meshes/left_back_turn.stl" />
      </geometry>
    </collision>
  </link>
  <joint
    name="left_back_turn"
    type="continuous">
    <origin
      xyz="0.5 -0.2635 0.181"
      rpy="0 0 0" />
    <parent
      link="base_link" />
    <child
      link="left_back_turn" />
    <axis
      xyz="0 0 -1" />
  </joint>
  <link
    name="left_back_rotate">
    <inertial>
      <origin
        xyz="-2.8162E-09 0.081079 0.057168"
        rpy="0 0 0" />
      <mass
        value="5" />
      <inertia
        ixx="0.00049107"
        ixy="-6.2566E-11"
        ixz="1.1975E-11"
        iyy="0.00040411"
        iyz="0.00013072"
        izz="0.00044131" />
    </inertial>
    <visual>
      <origin
        xyz="0 0 0"
        rpy="0 0 0" />
      <geometry>
        <mesh
          filename="package://ia_robot/meshes/left_back_rotate.stl" />
      </geometry>
      <material
        name="">
        <color
          rgba="0.89804 0.91765 0.92941 1" />
      </material>
    </visual>
    <collision>
      <origin
        xyz="0 0 0"
        rpy="0 0 0" />
      <geometry>
        <mesh
          filename="package://ia_robot/meshes/left_back_rotate.stl" />
      </geometry>
    </collision>
  </link>
  <joint
    name="left_back_rotate"
    type="continuous">
    <origin
      xyz="0.013811 0.017124 -0.101"
      rpy="1.5708 0 -0.67872" />
    <parent
      link="left_back_turn" />
    <child
      link="left_back_rotate" />
    <axis
      xyz="0 0 -1" />
  </joint>
  <link
    name="right_front_turn2">
    <inertial>
      <origin
        xyz="0.077388 -0.00042576 0.00053295"
        rpy="0 0 0" />
      <mass
        value="1" />
      <inertia
        ixx="0.00022184"
        ixy="8.1766E-06"
        ixz="4.2116E-05"
        iyy="0.001708"
        iyz="-2.3171E-07"
        izz="0.0019081" />
    </inertial>
    <visual>
      <origin
        xyz="0 0 0"
        rpy="0 0 0" />
      <geometry>
        <mesh
          filename="package://ia_robot/meshes/right_front_turn2.stl" />
      </geometry>
      <material
        name="">
        <color
          rgba="0.89804 0.91765 0.92941 1" />
      </material>
    </visual>
    <collision>
      <origin
        xyz="0 0 0"
        rpy="0 0 0" />
      <geometry>
        <mesh
          filename="package://ia_robot/meshes/right_front_turn2.stl" />
      </geometry>
    </collision>
  </link>
  <joint
    name="right_front_turn2"
    type="continuous">
    <origin
      xyz="-0.32 0.2635 0.2061"
      rpy="-3.1416 0 3.1416" />
    <parent
      link="base_link" />
    <child
      link="right_front_turn2" />
    <axis
      xyz="0 0 -1" />
  </joint>
  <link
    name="right_front_turn1">
    <inertial>
      <origin
        xyz="-0.027585 0.021815 -0.019921"
        rpy="0 0 0" />
      <mass
        value="0.2092" />
      <inertia
        ixx="0.00046046"
        ixy="2.4209E-05"
        ixz="-0.00010253"
        iyy="0.00047192"
        iyz="8.1083E-05"
        izz="0.00040411" />
    </inertial>
    <visual>
      <origin
        xyz="0 0 0"
        rpy="0 0 0" />
      <geometry>
        <mesh
          filename="package://ia_robot/meshes/right_front_turn1.stl" />
      </geometry>
      <material
        name="">
        <color
          rgba="0.89804 0.91765 0.92941 1" />
      </material>
    </visual>
    <collision>
      <origin
        xyz="0 0 0"
        rpy="0 0 0" />
      <geometry>
        <mesh
          filename="package://ia_robot/meshes/right_front_turn1.stl" />
      </geometry>
    </collision>
  </link>
  <joint
    name="right_front_turn1"
    type="continuous">
    <origin
      xyz="0.18 -0.00099028 0.0251"
      rpy="-3.1416 0 3.1416" />
    <parent
      link="right_front_turn2" />
    <child
      link="right_front_turn1" />
    <axis
      xyz="0 0 -1" />
  </joint>
  <link
    name="right_front_rotate">
    <inertial>
      <origin
        xyz="-0.00013528 -0.0001302 0.027435"
        rpy="0 0 0" />
      <mass
        value="5" />
      <inertia
        ixx="0.0024572"
        ixy="-9.458E-06"
        ixz="8.7888E-06"
        iyy="0.0024579"
        iyz="8.4584E-06"
        izz="0.0035968" />
    </inertial>
    <visual>
      <origin
        xyz="0 0 0"
        rpy="0 0 0" />
      <geometry>
        <mesh
          filename="package://ia_robot/meshes/right_front_rotate.stl" />
      </geometry>
      <material
        name="">
        <color
          rgba="1 1 1 1" />
      </material>
    </visual>
    <collision>
      <origin
        xyz="0 0 0"
        rpy="0 0 0" />
      <geometry>
        <mesh
          filename="package://ia_robot/meshes/right_front_rotate.stl" />
      </geometry>
    </collision>
  </link>
  <joint
    name="right_front_rotate"
    type="continuous">
    <origin
      xyz="0.017256 -0.013647 -0.101"
      rpy="-1.5708 0 0.90167" />
    <parent
      link="right_front_turn1" />
    <child
      link="right_front_rotate" />
    <axis
      xyz="0 0 -1" />
  </joint>
  <link
    name="left_front_turn2">
    <inertial>
      <origin
        xyz="-0.077197 0.005447 -0.00053295"
        rpy="0 0 0" />
      <mass
        value="1" />
      <inertia
        ixx="0.00022915"
        ixy="0.00010435"
        ixz="4.2012E-05"
        iyy="0.0017007"
        iyz="-2.9644E-06"
        izz="0.0019081" />
    </inertial>
    <visual>
      <origin
        xyz="0 0 0"
        rpy="0 0 0" />
      <geometry>
        <mesh
          filename="package://ia_robot/meshes/left_front_turn2.stl" />
      </geometry>
      <material
        name="">
        <color
          rgba="0.89804 0.91765 0.92941 1" />
      </material>
    </visual>
    <collision>
      <origin
        xyz="0 0 0"
        rpy="0 0 0" />
      <geometry>
        <mesh
          filename="package://ia_robot/meshes/left_front_turn2.stl" />
      </geometry>
    </collision>
  </link>
  <joint
    name="left_front_turn2"
    type="continuous">
    <origin
      xyz="-0.32 -0.2635 0.2061"
      rpy="0 0 0" />
    <parent
      link="base_link" />
    <child
      link="left_front_turn2" />
    <axis
      xyz="0 0 1" />
  </joint>
  <link
    name="left_front_turn1">
    <inertial>
      <origin
        xyz="-0.027412 0.022032 -0.019921"
        rpy="0 0 0" />
      <mass
        value="0.2092" />
      <inertia
        ixx="0.00046084"
        ixy="2.4297E-05"
        ixz="-0.00010189"
        iyy="0.00047154"
        iyz="8.1888E-05"
        izz="0.00040411" />
    </inertial>
    <visual>
      <origin
        xyz="0 0 0"
        rpy="0 0 0" />
      <geometry>
        <mesh
          filename="package://ia_robot/meshes/left_front_turn1.stl" />
      </geometry>
      <material
        name="">
        <color
          rgba="0.89804 0.91765 0.92941 1" />
      </material>
    </visual>
    <collision>
      <origin
        xyz="0 0 0"
        rpy="0 0 0" />
      <geometry>
        <mesh
          filename="package://ia_robot/meshes/left_front_turn1.stl" />
      </geometry>
    </collision>
  </link>
  <joint
    name="left_front_turn1"
    type="continuous">
    <origin
      xyz="-0.17955 0.012669 -0.0251"
      rpy="0 0 0" />
    <parent
      link="left_front_turn2" />
    <child
      link="left_front_turn1" />
    <axis
      xyz="0 0 -1" />
  </joint>
  <link
    name="left_front_rotate">
    <inertial>
      <origin
        xyz="0.00013528 0.0001302 0.027435"
        rpy="0 0 0" />
      <mass
        value="5" />
      <inertia
        ixx="0.0024572"
        ixy="-9.458E-06"
        ixz="-8.7888E-06"
        iyy="0.0024579"
        iyz="-8.4584E-06"
        izz="0.0035968" />
    </inertial>
    <visual>
      <origin
        xyz="0 0 0"
        rpy="0 0 0" />
      <geometry>
        <mesh
          filename="package://ia_robot/meshes/left_front_rotate.stl" />
      </geometry>
      <material
        name="">
        <color
          rgba="1 1 1 1" />
      </material>
    </visual>
    <collision>
      <origin
        xyz="0 0 0"
        rpy="0 0 0" />
      <geometry>
        <mesh
          filename="package://ia_robot/meshes/left_front_rotate.stl" />
      </geometry>
    </collision>
  </link>
  <joint
    name="left_front_rotate"
    type="continuous">
    <origin
      xyz="0.017148 -0.013782 -0.101"
      rpy="1.5708 0 -2.2478" />
    <parent
      link="left_front_turn1" />
    <child
      link="left_front_rotate" />
    <axis
      xyz="0 0 -1" />
  </joint>
  <link
    name="central_joint">
    <inertial>
      <origin
        xyz="0.046107 -0.0068668 0.17563"
        rpy="0 0 0" />
      <mass
        value="2" />
      <inertia
        ixx="0.0013326"
        ixy="0.00035164"
        ixz="1.1868E-14"
        iyy="0.0036412"
        iyz="8.0168E-14"
        izz="0.0047248" />
    </inertial>
    <visual>
      <origin
        xyz="0 0 0"
        rpy="0 0 0" />
      <geometry>
        <mesh
          filename="package://ia_robot/meshes/central_joint.stl" />
      </geometry>
      <material
        name="">
        <color
          rgba="0.75294 0.75294 0.75294 1" />
      </material>
    </visual>
    <collision>
      <origin
        xyz="0 0 0"
        rpy="0 0 0" />
      <geometry>
        <mesh
          filename="package://ia_robot/meshes/central_joint.stl" />
      </geometry>
    </collision>
  </link>
  <joint
    name="central_joint"
    type="continuous">
    <origin
      xyz="0.12 -0.17563 1"
      rpy="1.5708 0 3.1416" />
    <parent
      link="base_link" />
    <child
      link="central_joint" />
    <axis
      xyz="0 0 -1" />
  </joint>
  <link
    name="left_joint2">
    <inertial>
      <origin
        xyz="-0.20187 -0.013769 0.041537"
        rpy="0 0 0" />
      <mass
        value="1.5" />
      <inertia
        ixx="0.00057175"
        ixy="-7.2991E-05"
        ixz="0.00011078"
        iyy="0.0016326"
        iyz="7.8567E-06"
        izz="0.0015727" />
    </inertial>
    <visual>
      <origin
        xyz="0 0 0"
        rpy="0 0 0" />
      <geometry>
        <mesh
          filename="package://ia_robot/meshes/left_joint2.stl" />
      </geometry>
      <material
        name="">
        <color
          rgba="0.75294 0.75294 0.75294 1" />
      </material>
    </visual>
    <collision>
      <origin
        xyz="0 0 0"
        rpy="0 0 0" />
      <geometry>
        <mesh
          filename="package://ia_robot/meshes/left_joint2.stl" />
      </geometry>
    </collision>
  </link>
  <joint
    name="left_joint2"
    type="continuous">
    <origin
      xyz="0.19287 -0.028726 -0.0358"
      rpy="-3.1416 0 3.1416" />
    <parent
      link="central_joint" />
    <child
      link="left_joint2" />
    <axis
      xyz="0 0 1" />
  </joint>
  <link
    name="left_joint3">
    <inertial>
      <origin
        xyz="-0.00086226 2.9323E-05 -0.021114"
        rpy="0 0 0" />
      <mass
        value="1" />
      <inertia
        ixx="0.00021167"
        ixy="2.7958E-06"
        ixz="-1.1066E-05"
        iyy="0.00028182"
        iyz="3.9014E-07"
        izz="0.00028636" />
    </inertial>
    <visual>
      <origin
        xyz="0 0 0"
        rpy="0 0 0" />
      <geometry>
        <mesh
          filename="package://ia_robot/meshes/left_joint3.stl" />
      </geometry>
      <material
        name="">
        <color
          rgba="0.75294 0.75294 0.75294 1" />
      </material>
    </visual>
    <collision>
      <origin
        xyz="0 0 0"
        rpy="0 0 0" />
      <geometry>
        <mesh
          filename="package://ia_robot/meshes/left_joint3.stl" />
      </geometry>
    </collision>
  </link>
  <joint
    name="left_joint3"
    type="continuous">
    <origin
      xyz="-0.6041 -0.041203 0.0592"
      rpy="0.0681 1.5708 0" />
    <parent
      link="left_joint2" />
    <child
      link="left_joint3" />
    <axis
      xyz="0 0 -1" />
  </joint>
  <link
    name="left_joint4">
    <inertial>
      <origin
        xyz="0.12398 0.036321 0.038483"
        rpy="0 0 0" />
      <mass
        value="1" />
      <inertia
        ixx="0.00066488"
        ixy="-0.00023186"
        ixz="-5.7043E-05"
        iyy="0.0013883"
        iyz="-3.6165E-05"
        izz="0.0016805" />
    </inertial>
    <visual>
      <origin
        xyz="0 0 0"
        rpy="0 0 0" />
      <geometry>
        <mesh
          filename="package://ia_robot/meshes/left_joint4.stl" />
      </geometry>
      <material
        name="">
        <color
          rgba="0.75294 0.75294 0.75294 1" />
      </material>
    </visual>
    <collision>
      <origin
        xyz="0 0 0"
        rpy="0 0 0" />
      <geometry>
        <mesh
          filename="package://ia_robot/meshes/left_joint4.stl" />
      </geometry>
    </collision>
  </link>
  <joint
    name="left_joint4"
    type="continuous">
    <origin
      xyz="-0.056454 0.0022711 -0.064"
      rpy="1.5708 1.5026 1.5306" />
    <parent
      link="left_joint3" />
    <child
      link="left_joint4" />
    <axis
      xyz="0 0 1" />
  </joint>
  <link
    name="right_joint2">
    <inertial>
      <origin
        xyz="0.20233 -0.0023768 0.041537"
        rpy="0 0 0" />
      <mass
        value="1.5" />
      <inertia
        ixx="0.0005669"
        ixy="1.228E-05"
        ixz="-0.00011106"
        iyy="0.0016374"
        iyz="1.0046E-06"
        izz="0.0015727" />
    </inertial>
    <visual>
      <origin
        xyz="0 0 0"
        rpy="0 0 0" />
      <geometry>
        <mesh
          filename="package://ia_robot/meshes/right_joint2.stl" />
      </geometry>
      <material
        name="">
        <color
          rgba="0.75294 0.75294 0.75294 1" />
      </material>
    </visual>
    <collision>
      <origin
        xyz="0 0 0"
        rpy="0 0 0" />
      <geometry>
        <mesh
          filename="package://ia_robot/meshes/right_joint2.stl" />
      </geometry>
    </collision>
  </link>
  <joint
    name="right_joint2"
    type="continuous">
    <origin
      xyz="0.19287 -0.028725 0.38706"
      rpy="0 0 0" />
    <parent
      link="central_joint" />
    <child
      link="right_joint2" />
    <axis
      xyz="0 0 1" />
  </joint>
  <link
    name="right_joint3">
    <inertial>
      <origin
        xyz="0.0007133 0.00048552 -0.021114"
        rpy="0 0 0" />
      <mass
        value="1" />
      <inertia
        ixx="0.00023347"
        ixy="-3.2581E-05"
        ixz="9.1612E-06"
        iyy="0.00026002"
        iyz="6.2196E-06"
        izz="0.00028636" />
    </inertial>
    <visual>
      <origin
        xyz="0 0 0"
        rpy="0 0 0" />
      <geometry>
        <mesh
          filename="package://ia_robot/meshes/right_joint3.stl" />
      </geometry>
      <material
        name="">
        <color
          rgba="0.75294 0.75294 0.75294 1" />
      </material>
    </visual>
    <collision>
      <origin
        xyz="0 0 0"
        rpy="0 0 0" />
      <geometry>
        <mesh
          filename="package://ia_robot/meshes/right_joint3.stl" />
      </geometry>
    </collision>
  </link>
  <joint
    name="right_joint3"
    type="continuous">
    <origin
      xyz="0.60546 -0.0071123 0.0592"
      rpy="3.1298 -1.5708 0" />
    <parent
      link="right_joint2" />
    <child
      link="right_joint3" />
    <axis
      xyz="0 0 -1" />
  </joint>
  <link
    name="right_joint4">
    <inertial>
      <origin
        xyz="-0.12299 -0.039531 0.038483"
        rpy="0 0 0" />
      <mass
        value="1" />
      <inertia
        ixx="0.00067742"
        ixy="-0.00025034"
        ixz="5.6084E-05"
        iyy="0.0013758"
        iyz="3.7636E-05"
        izz="0.0016805" />
    </inertial>
    <visual>
      <origin
        xyz="0 0 0"
        rpy="0 0 0" />
      <geometry>
        <mesh
          filename="package://ia_robot/meshes/right_joint4.stl" />
      </geometry>
      <material
        name="">
        <color
          rgba="0.75294 0.75294 0.75294 1" />
      </material>
    </visual>
    <collision>
      <origin
        xyz="0 0 0"
        rpy="0 0 0" />
      <geometry>
        <mesh
          filename="package://ia_robot/meshes/right_joint4.stl" />
      </geometry>
    </collision>
  </link>
  <joint
    name="right_joint4"
    type="continuous">
    <origin
      xyz="0.046902 0.031503 -0.064"
      rpy="1.5708 -1.5566 -0.97933" />
    <parent
      link="right_joint3" />
    <child
      link="right_joint4" />
    <axis
      xyz="0 0 1" />
  </joint>
</robot>